<?xml version="1.0" ?>
<!-- =================================================================================== -->
<!-- |    This document was autogenerated by xacro from /home/tymoteusz/ros2_ws/src/elfin_robot_ros2/elfin_description/urdf/elfin5_l.urdf.xacro | -->
<!-- |    EDITING THIS FILE BY HAND IS NOT RECOMMENDED                                 | -->
<!-- =================================================================================== -->
<robot name="elfin5_l">
  <material name="black">
    <color rgba="0.0 0.0 0.0 1.0"/>
  </material>
  <material name="blue">
    <color rgba="0.0 0.0 0.8 1.0"/>
  </material>
  <material name="green">
    <color rgba="0.0 0.8 0.0 1.0"/>
  </material>
  <material name="grey">
    <color rgba="0.2 0.2 0.2 1.0"/>
  </material>
  <material name="orange">
    <color rgba="1.0 0.4235294117647059 0.0392156862745098 1.0"/>
  </material>
  <material name="brown">
    <color rgba="0.8705882352941177 0.8117647058823529 0.7647058823529411 1.0"/>
  </material>
  <material name="red">
    <color rgba="0.8 0.0 0.0 1.0"/>
  </material>
  <material name="white">
    <color rgba="1.0 1.0 1.0 1.0"/>
  </material>
  <material name="metal">
    <color rgba="0.768627450980392 0.749019607843137 0.729411764705882 1"/>
  </material>
  <material name="metal_grey">
    <color rgba="0.501960784313725 0.501960784313725 0.501960784313725 1"/>
  </material>
  <material name="metal_white">
    <color rgba="0.866666666666667 0.866666666666667 0.890196078431373 1"/>
  </material>
  <!-- ros_control plugin -->
  <!-- <gazebo>
    <plugin name="gazebo_ros2_control" filename="libgazebo_ros2_control.so">
      <robotSimType>gazebo_ros2_control/DefaultRobotHWSim</robotSimType>
      <legacyModeNS>true</legacyModeNS>
    </plugin>
  </gazebo> -->
  <gazebo>
    <plugin filename="gazebo_ros_control.so" name="gazebo_ros2_control">
      <robot_sim_type>gazebo_ros_control/GazeboSystem</robot_sim_type>
      <legacyModeNS>true</legacyModeNS>
    </plugin>
  </gazebo>
  <gazebo reference="elfin_link2">
    <visual name="visual">
      <material>
        <script>
          <uri>file://media/materials/scripts/gazebo.material</uri>
          <name>Gazebo/Grey</name>
        </script>
      </material>
    </visual>
  </gazebo>
  <gazebo reference="elfin_link4">
    <visual name="visual">
      <material>
        <script>
          <uri>file://media/materials/scripts/gazebo.material</uri>
          <name>Gazebo/Grey</name>
        </script>
      </material>
    </visual>
  </gazebo>
  <transmission name="elfin_joint1_trans">
    <type>transmission_interface/SimpleTransmission</type>
    <joint name="elfin_joint1">
      <hardwareInterface>hardware_interface/PositionJointInterface</hardwareInterface>
    </joint>
    <actuator name="elfin_joint1_motor">
      <mechanicalReduction>1</mechanicalReduction>
    </actuator>
  </transmission>
  <transmission name="elfin_joint2_trans">
    <type>transmission_interface/SimpleTransmission</type>
    <joint name="elfin_joint2">
      <hardwareInterface>hardware_interface/PositionJointInterface</hardwareInterface>
    </joint>
    <actuator name="elfin_joint2_motor">
      <mechanicalReduction>1</mechanicalReduction>
    </actuator>
  </transmission>
  <transmission name="elfin_joint3_trans">
    <type>transmission_interface/SimpleTransmission</type>
    <joint name="elfin_joint3">
      <hardwareInterface>hardware_interface/PositionJointInterface</hardwareInterface>
    </joint>
    <actuator name="elfin_joint3_motor">
      <mechanicalReduction>1</mechanicalReduction>
    </actuator>
  </transmission>
  <transmission name="elfin_joint4_trans">
    <type>transmission_interface/SimpleTransmission</type>
    <joint name="elfin_joint4">
      <hardwareInterface>hardware_interface/PositionJointInterface</hardwareInterface>
    </joint>
    <actuator name="elfin_joint4_motor">
      <mechanicalReduction>1</mechanicalReduction>
    </actuator>
  </transmission>
  <transmission name="elfin_joint5_trans">
    <type>transmission_interface/SimpleTransmission</type>
    <joint name="elfin_joint5">
      <hardwareInterface>hardware_interface/PositionJointInterface</hardwareInterface>
    </joint>
    <actuator name="elfin_joint5_motor">
      <mechanicalReduction>1</mechanicalReduction>
    </actuator>
  </transmission>
  <transmission name="elfin_joint6_trans">
    <type>transmission_interface/SimpleTransmission</type>
    <joint name="elfin_joint6">
      <hardwareInterface>hardware_interface/PositionJointInterface</hardwareInterface>
    </joint>
    <actuator name="elfin_joint6_motor">
      <mechanicalReduction>1</mechanicalReduction>
    </actuator>
  </transmission>
  <link name="world"/>
  <joint name="world_base" type="fixed">
    <origin rpy="0 0 0" xyz="0 0 0"/>
    <parent link="world"/>
    <child link="elfin_base_link"/>
  </joint>
  <link name="elfin_base_link">
  <collision>
    <origin rpy="0 0 0" xyz="0 0 0"/>
    <geometry>
      <box size="0.001 0.001 0.001"/>
    </geometry>
  </collision>
  </link>
  <joint name="elfin_base_joint" type="fixed">
    <origin rpy="0 0 1.5708" xyz="0 0 0"/>
    <parent link="elfin_base_link"/>
    <child link="elfin_base"/>
  </joint>
  <link name="elfin_base">
    <inertial>
      <origin rpy="0 0 0" xyz="0.00022093 0.0013404 0.025529"/>
      <mass value="0.68795"/>
      <inertia ixx="0.0012704" ixy="6.1256E-06" ixz="1.9788E-06" iyy="0.0013413" iyz="1.2007E-05" izz="0.0022564"/>
    </inertial>
    <visual>
      <origin rpy="0 0 0" xyz="0 0 0"/>
      <geometry>
        <mesh filename="../meshes/elfin_base.STL"/>
      </geometry>
      <material name="">
        <color rgba="0.79216 0.81961 0.92941 1"/>
      </material>
    </visual>
    <collision>
      <origin rpy="0 0 0" xyz="0 0 0"/>
      <geometry>
        <mesh filename="../meshes/elfin_base.STL" scale="1.1 1.1 1.1"/>
      </geometry>
    </collision>
  </link>
  <link name="elfin_link1">
    <inertial>
      <origin rpy="0 0 0" xyz="-0.021818 0.13889 0.000013458"/>
      <mass value="2.5856"/>
      <inertia ixx="0.012636" ixy="0.0034176" ixz="-1.9559E-06" iyy="0.0066118" iyz="-1.7982E-06" izz="0.014362"/>
    </inertial>
    <visual>
      <origin rpy="0 0 0" xyz="0 0 0"/>
      <geometry>
        <mesh filename="../meshes/elfin_link1.STL"/>
      </geometry>
      <material name="">
        <color rgba="0.77255 0.75294 0.73333 1"/>
      </material>
    </visual>
    <collision>
      <origin rpy="0 0 0" xyz="0 0 0"/>
      <geometry>
        <mesh filename="../meshes/elfin_link1.STL" scale="1.1 1.1 1.1"/>
      </geometry>
    </collision>
  </link>
  <joint name="elfin_joint1" type="revolute">
    <origin rpy="1.5708 0 0" xyz="0 0 0.03"/>
    <parent link="elfin_base"/>
    <child link="elfin_link1"/>
    <axis xyz="0 1 0"/>
    <limit effort="420" lower="-3.14" upper="3.14" velocity="1.57"/>
  </joint>
  <link name="elfin_link2">
    <inertial>
      <origin rpy="0 0 0" xyz="-0.032497 0.30341 -7.6521E-05"/>
      <mass value="1.208607"/>
      <inertia ixx="0.02975970" ixy="-0.00126441" ixz="-0.00000024" iyy="0.00168156" iyz="-0.0000021" izz="0.02944694"/>
    </inertial>
    <visual>
      <origin rpy="0 0 0" xyz="0 0 0"/>
      <geometry>
        <mesh filename="../meshes/elfin_link2.STL"/>
      </geometry>
      <material name="">
        <color rgba="0.68627 0.68627 0.68627 1"/>
      </material>
    </visual>
    <collision>
      <origin rpy="0 0 0" xyz="0 0 0"/>
      <geometry>
        <mesh filename="../meshes/elfin_link2.STL" scale="1.1 1.1 1.1"/>
      </geometry>
    </collision>
  </link>
  <joint name="elfin_joint2" type="revolute">
    <origin rpy="0 0 0" xyz="-0.087 0.19 0"/>
    <parent link="elfin_link1"/>
    <child link="elfin_link2"/>
    <axis xyz="-1 0 0"/>
    <limit effort="420" lower="-2.35" upper="2.35" velocity="1.57"/>
  </joint>
  <link name="elfin_link3">
    <inertial>
      <origin rpy="0 0 0" xyz="0.067584 -0.041479 -1.1421E-05"/>
      <mass value="1.5324"/>
      <inertia ixx="0.00514" ixy="0.0014834" ixz="-5.7782E-07" iyy="0.0028926" iyz="-3.0654E-07" izz="0.0060883"/>
    </inertial>
    <visual>
      <origin rpy="0 0 0" xyz="0 0 0"/>
      <geometry>
        <mesh filename="../meshes/elfin_link3.STL"/>
      </geometry>
      <material name="">
        <color rgba="0.86667 0.86667 0.8902 1"/>
      </material>
    </visual>
    <collision>
      <origin rpy="0 0 0" xyz="0 0 0"/>
      <geometry>
        <mesh filename="../meshes/elfin_link3.STL" scale="1.1 1.1 1.1"/>
      </geometry>
    </collision>
  </link>
  <joint name="elfin_joint3" type="revolute">
    <origin rpy="-3.1416 0 0" xyz="0 0.385 0"/>
    <parent link="elfin_link2"/>
    <child link="elfin_link3"/>
    <axis xyz="1 0 0"/>
    <limit effort="200" lower="-2.61" upper="2.61" velocity="1.57"/>
  </joint>
  <link name="elfin_link4">
    <inertial>
      <origin rpy="0 0 0" xyz="-0.017434 -0.33294 -0.00015134"/>
      <mass value="0.5"/>
      <inertia ixx="0.00542441" ixy="0.0020749" ixz="1.0501E-05" iyy="0.014338" iyz="-0.00041574" izz="0.00607489"/>
    </inertial>
    <visual>
      <origin rpy="0 0 0" xyz="0 0 0"/>
      <geometry>
        <mesh filename="../meshes/elfin_link4.STL"/>
      </geometry>
      <material name="">
        <color rgba="0.68627 0.68627 0.68627 1"/>
      </material>
    </visual>
    <collision>
      <origin rpy="0 0 0" xyz="0 0 0"/>
      <geometry>
        <mesh filename="../meshes/elfin_link4.STL" scale="1.1 1.1 1.1"/>
      </geometry>
    </collision>
  </link>
  <joint name="elfin_joint4" type="revolute">
    <origin rpy="3.1416 0 0" xyz="0.087 -0.1255 0"/>
    <parent link="elfin_link3"/>
    <child link="elfin_link4"/>
    <axis xyz="0 1 0"/>
    <limit effort="200" lower="-3.14" upper="3.14" velocity="1.57"/>
  </joint>
  <link name="elfin_link5">
    <inertial>
      <origin rpy="0 0 0" xyz="-0.015972 -0.036591 1.4235E-06"/>
      <mass value="0.81192"/>
      <inertia ixx="0.0018901" ixy="0.00056728" ixz="-4.2025E-08" iyy="0.0010231" iyz="5.0791E-09" izz="0.002299"/>
    </inertial>
    <visual>
      <origin rpy="0 0 0" xyz="0 0 0"/>
      <geometry>
        <mesh filename="../meshes/elfin_link5.STL"/>
      </geometry>
      <material name="">
        <color rgba="0.79216 0.81961 0.93333 1"/>
      </material>
    </visual>
    <collision>
      <origin rpy="0 0 0" xyz="0 0 0"/>
      <geometry>
        <mesh filename="../meshes/elfin_link5.STL" scale="1.1 1.1 1.1"/>
      </geometry>
    </collision>
  </link>
  <joint name="elfin_joint5" type="revolute">
    <origin rpy="-3.1416 0 0" xyz="0 0.3095 0"/>
    <parent link="elfin_link4"/>
    <child link="elfin_link5"/>
    <axis xyz="1 0 0"/>
    <limit effort="69" lower="-2.56" upper="2.56" velocity="1.57"/>
  </joint>
  <link name="elfin_link6">
    <inertial>
      <origin rpy="0 0 0" xyz="-0.0072549 0.027062 3.208E-05"/>
      <mass value="0.11343"/>
      <inertia ixx="7.4923E-05" ixy="-2.3429E-06" ixz="-1.8394E-07" iyy="0.0001278" iyz="-4.8092E-08" izz="7.6653E-05"/>
    </inertial>
    <visual>
      <origin rpy="0 0 0" xyz="0 0 0"/>
      <geometry>
        <mesh filename="../meshes/elfin_link6.STL"/>
      </geometry>
      <material name="">
        <color rgba="0.77647 0.75686 0.73725 1"/>
      </material>
    </visual>
    <collision>
      <origin rpy="0 0 0" xyz="0 0 0"/>
      <geometry>
        <mesh filename="../meshes/elfin_link6.STL" scale="1.1 1.1 1.1"/>
      </geometry>
    </collision>
  </link>
  <joint name="elfin_joint6" type="revolute">
    <origin rpy="3.1416 0 0" xyz="0 -0.1065 0"/>
    <parent link="elfin_link5"/>
    <child link="elfin_link6"/>
    <axis xyz="0 1 0"/>
    <limit effort="69" lower="-3.14" upper="3.14" velocity="1.57"/>
  </joint>
  <link name="elfin_end_link">
  <visual>
    <origin rpy="0 0 0" xyz="0 0 0"/>
    <box size="0.0015 0.0015 0.0015"/>
    <material name="red"><color rgba="0.8 0.0 0.0 1.0"/></material>
  </visual>
  <collision>
    <origin rpy="0 0 0" xyz="0 0 0"/>
    <geometry>
      <box size="0.001 0.001 0.001"/>
    </geometry>
  </collision>
  </link>
  <joint name="elfin_end_joint" type="fixed">
    <origin rpy="0 0 0" xyz="0 0 0"/>
    <parent link="elfin_link6"/>
    <child link="elfin_end_link"/>
    <axis xyz="0 0 0"/>
  </joint>
</robot>