<?xml version="1.0" encoding="utf-8"?>
<robot name="elfin5_l">

  <!-- Links -->
  <link name="elfin_base_link"/>
  <link name="elfin_base"/>
  <link name="elfin_link1"/>
  <link name="elfin_link2"/>
  <link name="elfin_link3"/>
  <link name="elfin_link4"/>
  <link name="elfin_link5"/>
  <link name="elfin_link6"/>
  <link name="elfin_end_link"/>

  <!-- Fixed: base_link -> base -->
  <joint name="elfin_base_joint" type="fixed">
    <parent link="elfin_base_link"/>
    <child link="elfin_base"/>
    <origin xyz="0 0 0" rpy="0 0 1.5708"/>
  </joint>

  <joint name="elfin_joint1" type="revolute">
    <parent link="elfin_base"/>
    <child link="elfin_link1"/>
    <origin xyz="0 0 0.03" rpy="1.5708 0 0"/>
    <axis xyz="0 1 0"/>
    <limit lower="-3.14" upper="3.14"/>
  </joint>

  <joint name="elfin_joint2" type="revolute">
    <parent link="elfin_link1"/>
    <child link="elfin_link2"/>
    <origin xyz="-0.087 0.19 0" rpy="0 0 0"/>
    <axis xyz="-1 0 0"/>
    <limit lower="-2.35" upper="2.35"/>
  </joint>

  <joint name="elfin_joint3" type="revolute">
    <parent link="elfin_link2"/>
    <child link="elfin_link3"/>
    <origin xyz="0 0.385 0" rpy="-3.1416 0 0"/>
    <axis xyz="1 0 0"/>
    <limit lower="-2.61" upper="2.61"/>
  </joint>

  <joint name="elfin_joint4" type="revolute">
    <parent link="elfin_link3"/>
    <child link="elfin_link4"/>
    <origin xyz="0.087 -0.1255 0" rpy="3.1416 0 0"/>
    <axis xyz="0 1 0"/>
    <limit lower="-3.14" upper="3.14"/>
  </joint>

  <joint name="elfin_joint5" type="revolute">
    <parent link="elfin_link4"/>
    <child link="elfin_link5"/>
    <origin xyz="0 0.3095 0" rpy="-3.1416 0 0"/>
    <axis xyz="1 0 0"/>
    <limit lower="-2.56" upper="2.56"/>
  </joint>

  <joint name="elfin_joint6" type="revolute">
    <parent link="elfin_link5"/>
    <child link="elfin_link6"/>
    <origin xyz="0 -0.1065 0" rpy="3.1416 0 0"/>
    <axis xyz="0 1 0"/>
    <limit lower="-3.14" upper="3.14"/>
  </joint>

  <joint name="elfin_end_joint" type="fixed">
    <parent link="elfin_link6"/>
    <child link="elfin_end_link"/>
    <origin xyz="0 0 0" rpy="0 0 0"/>
  </joint>

</robot>
