<?xml version="1.0" encoding="utf-8"?>
<robot name="elfin5_l">

  <!-- Links -->

  <link name="elfin_base_link">
    <visual>
      <origin xyz="0 0 0" rpy="0 0 0"/>
      <geometry>
        <box size="0.001 0.001 0.001"/>
      </geometry>
      <material name="black">
        <color rgba="0.0 0.0 0.0 1.0"/>
      </material>
    </visual>
    <collision>
      <origin xyz="0 0 0" rpy="0 0 0"/>
      <geometry>
        <box size="0.001 0.001 0.001"/>
      </geometry>
    </collision>
  </link>

  <link name="elfin_base">
    <inertial>
      <origin xyz="0.00022093 0.0013404 0.025529" rpy="0 0 0"/>
      <mass value="0.68795"/>
      <inertia ixx="0.0012704" ixy="6.1256E-06" ixz="1.9788E-06"
               iyy="0.0013413" iyz="1.2007E-05" izz="0.0022564"/>
    </inertial>
    <visual>
      <origin xyz="0 0 0" rpy="0 0 0"/>
      <geometry>
        <mesh filename="../meshes/elfin_base.STL"/>
      </geometry>
      <material name="metal_white">
        <color rgba="0.79216 0.81961 0.92941 1"/>
      </material>
    </visual>
    <collision>
      <origin xyz="0 0 0" rpy="0 0 0"/>
      <geometry>
        <mesh filename="../meshes/elfin_base.STL" scale="1.2 1.2 1.2"/>
      </geometry>
    </collision>
  </link>

  <link name="elfin_link1">
    <inertial>
      <origin xyz="-0.021818 0.13889 0.000013458" rpy="0 0 0"/>
      <mass value="2.5856"/>
      <inertia ixx="0.012636" ixy="0.0034176" ixz="-1.9559E-06"
               iyy="0.0066118" iyz="-1.7982E-06" izz="0.014362"/>
    </inertial>
    <visual>
      <origin xyz="0 0 0" rpy="0 0 0"/>
      <geometry>
        <mesh filename="../meshes/elfin_link1.STL"/>
      </geometry>
      <material name="metal">
        <color rgba="0.77255 0.75294 0.73333 1"/>
      </material>
    </visual>
    <collision>
      <origin xyz="0 0 0" rpy="0 0 0"/>
      <geometry>
        <mesh filename="../meshes/elfin_link1.STL" scale="1.2 1.2 1.2"/>
      </geometry>
    </collision>
  </link>

  <link name="elfin_link2">
    <inertial>
      <origin xyz="-0.032497 0.30341 -7.6521E-05" rpy="0 0 0"/>
      <mass value="1.208607"/>
      <inertia ixx="0.02975970" ixy="-0.00126441" ixz="-0.00000024"
               iyy="0.00168156" iyz="-0.0000021" izz="0.02944694"/>
    </inertial>
    <visual>
      <origin xyz="0 0 0" rpy="0 0 0"/>
      <geometry>
        <mesh filename="../meshes/elfin_link2.STL"/>
      </geometry>
      <material name="metal_grey">
        <color rgba="0.68627 0.68627 0.68627 1"/>
      </material>
    </visual>
    <collision>
      <origin xyz="0 0 0" rpy="0 0 0"/>
      <geometry>
        <mesh filename="../meshes/elfin_link2.STL" scale="1.2 1.2 1.2"/>
      </geometry>
    </collision>
  </link>

  <link name="elfin_link3">
    <inertial>
      <origin xyz="0.067584 -0.041479 -1.1421E-05" rpy="0 0 0"/>
      <mass value="1.5324"/>
      <inertia ixx="0.00514" ixy="0.0014834" ixz="-5.7782E-07"
               iyy="0.0028926" iyz="-3.0654E-07" izz="0.0060883"/>
    </inertial>
    <visual>
      <origin xyz="0 0 0" rpy="0 0 0"/>
      <geometry>
        <mesh filename="../meshes/elfin_link3.STL"/>
      </geometry>
      <material name="metal_white">
        <color rgba="0.86667 0.86667 0.8902 1"/>
      </material>
    </visual>
    <collision>
      <origin xyz="0 0 0" rpy="0 0 0"/>
      <geometry>
        <mesh filename="../meshes/elfin_link3.STL" scale="1.2 1.2 1.2"/>
      </geometry>
    </collision>
  </link>

  <link name="elfin_link4">
    <inertial>
      <origin xyz="-0.017434 -0.33294 -0.00015134" rpy="0 0 0"/>
      <mass value="0.5"/>
      <inertia ixx="0.00542441" ixy="0.0020749" ixz="1.0501E-05"
               iyy="0.014338" iyz="-0.00041574" izz="0.00607489"/>
    </inertial>
    <visual>
      <origin xyz="0 0 0" rpy="0 0 0"/>
      <geometry>
        <mesh filename="../meshes/elfin_link4.STL"/>
      </geometry>
      <material name="metal_grey">
        <color rgba="0.68627 0.68627 0.68627 1"/>
      </material>
    </visual>
    <collision>
      <origin xyz="0 0 0" rpy="0 0 0"/>
      <geometry>
        <mesh filename="../meshes/elfin_link4.STL" scale="1.2 1.2 1.2"/>
      </geometry>
    </collision>
  </link>

  <link name="elfin_link5">
    <inertial>
      <origin xyz="-0.015972 -0.036591 1.4235E-06" rpy="0 0 0"/>
      <mass value="0.81192"/>
      <inertia ixx="0.0018901" ixy="0.00056728" ixz="-4.2025E-08"
               iyy="0.0010231" iyz="5.0791E-09" izz="0.002299"/>
    </inertial>
    <visual>
      <origin xyz="0 0 0" rpy="0 0 0"/>
      <geometry>
        <mesh filename="../meshes/elfin_link5.STL"/>
      </geometry>
      <material name="metal_white">
        <color rgba="0.79216 0.81961 0.93333 1"/>
      </material>
    </visual>
    <collision>
      <origin xyz="0 0 0" rpy="0 0 0"/>
      <geometry>
        <mesh filename="../meshes/elfin_link5.STL" scale="1.2 1.2 1.2"/>
      </geometry>
    </collision>
  </link>

  <link name="elfin_link6">
    <inertial>
      <origin xyz="-0.0072549 0.027062 3.208E-05" rpy="0 0 0"/>
      <mass value="0.11343"/>
      <inertia ixx="7.4923E-05" ixy="-2.3429E-06" ixz="-1.8394E-07"
               iyy="0.0001278" iyz="-4.8092E-08" izz="7.6653E-05"/>
    </inertial>
    <visual>
      <origin xyz="0 0 0" rpy="0 0 0"/>
      <geometry>
        <mesh filename="../meshes/elfin_link6.STL"/>
      </geometry>
      <material name="metal">
        <color rgba="0.77647 0.75686 0.73725 1"/>
      </material>
    </visual>
    <collision>
      <origin xyz="0 0 0" rpy="0 0 0"/>
      <geometry>
        <mesh filename="../meshes/elfin_link6.STL" scale="1.2 1.2 1.2"/>
      </geometry>
    </collision>
  </link>

  <link name="elfin_end_link">
    <visual>
      <origin xyz="0 0 0" rpy="0 0 0"/>
      <geometry>
        <box size="0.0015 0.0015 0.0015"/>
      </geometry>
      <material name="red">
        <color rgba="0.8 0.0 0.0 1.0"/>
      </material>
    </visual>
    <collision>
      <origin xyz="0 0 0" rpy="0 0 0"/>
      <geometry>
        <box size="0.001 0.001 0.001"/>
      </geometry>
    </collision>
  </link>

  <!-- Joints -->

  <joint name="elfin_base_joint" type="fixed">
    <parent link="elfin_base_link"/>
    <child link="elfin_base"/>
    <origin xyz="0 0 0" rpy="0 0 1.5708"/>
  </joint>

  <joint name="elfin_joint1" type="revolute">
    <parent link="elfin_base"/>
    <child link="elfin_link1"/>
    <origin xyz="0 0 0.03" rpy="1.5708 0 0"/>
    <axis xyz="0 1 0"/>
    <limit lower="-3.14" upper="3.14" effort="420" velocity="1.57"/>
  </joint>

  <joint name="elfin_joint2" type="revolute">
    <parent link="elfin_link1"/>
    <child link="elfin_link2"/>
    <origin xyz="-0.087 0.19 0" rpy="0 0 0"/>
    <axis xyz="-1 0 0"/>
    <limit lower="-2.35" upper="2.35" effort="420" velocity="1.57"/>
  </joint>

  <joint name="elfin_joint3" type="revolute">
    <parent link="elfin_link2"/>
    <child link="elfin_link3"/>
    <origin xyz="0 0.385 0" rpy="-3.1416 0 0"/>
    <axis xyz="1 0 0"/>
    <limit lower="-2.61" upper="2.61" effort="200" velocity="1.57"/>
  </joint>

  <joint name="elfin_joint4" type="revolute">
    <parent link="elfin_link3"/>
    <child link="elfin_link4"/>
    <origin xyz="0.087 -0.1255 0" rpy="3.1416 0 0"/>
    <axis xyz="0 1 0"/>
    <limit lower="-3.14" upper="3.14" effort="200" velocity="1.57"/>
  </joint>

  <joint name="elfin_joint5" type="revolute">
    <parent link="elfin_link4"/>
    <child link="elfin_link5"/>
    <origin xyz="0 0.3095 0" rpy="-3.1416 0 0"/>
    <axis xyz="1 0 0"/>
    <limit lower="-2.56" upper="2.56" effort="69" velocity="1.57"/>
  </joint>

  <joint name="elfin_joint6" type="revolute">
    <parent link="elfin_link5"/>
    <child link="elfin_link6"/>
    <origin xyz="0 -0.1065 0" rpy="3.1416 0 0"/>
    <axis xyz="0 1 0"/>
    <limit lower="-3.14" upper="3.14" effort="69" velocity="1.57"/>
  </joint>

  <joint name="elfin_end_joint" type="fixed">
    <parent link="elfin_link6"/>
    <child link="elfin_end_link"/>
    <origin xyz="0 0 0" rpy="0 0 0"/>
  </joint>

</robot>
